<?xml version="1.0" ?>
<!--This file contains the SDF model of a KUKA iiwa robot with a wsg50 gripper.
    It has been produced from the varients in //third_party/robotics/models.
    Note:  This file is temporary, and should be deleted once Bullet supports
    importing models in SDF.  Also, this file has been specialized for Bullet,
    because the mass of the base link has been set to 0, as needed by Bullet.
    Note:  All of the gripper link poses have been adjusted in the z direction
    to achieve a reasonable position of the gripper relative to the arm.
    Note: The joint names for the KUKA have been changed to J0, J1, etc. -->
<sdf version='1.6'>
  <world name='default'>
  <model name='lbr_iiwa_with_wsg50'>
    <link name='lbr_iiwa_link_0'>
      <pose frame=''>0 0 0 0 -0 0</pose>
      <inertial>
        <pose frame=''>-0.1 0 0.07 0 -0 0</pose>
        <mass>0</mass>
        <inertia>
          <ixx>0.05</ixx>
          <ixy>0</ixy>
          <ixz>0</ixz>
          <iyy>0.06</iyy>
          <iyz>0</iyz>
          <izz>0.03</izz>
        </inertia>
      </inertial>
      <collision name='lbr_iiwa_link_0_collision'>
        <pose frame=''>0 0 0 0 -0 0</pose>
        <geometry>
          <mesh>
            <scale>1 1 1</scale>
            <uri>/meshes/link_0.stl</uri>
          </mesh>
        </geometry>
      </collision>
      <visual name='lbr_iiwa_link_0_visual'>
        <pose frame=''>0 0 0 0 -0 0</pose>
        <geometry>
          <mesh>
            <scale>1 1 1</scale>
            <uri>meshes/link_0.obj</uri>
          </mesh>
        </geometry>
        <material>
          <ambient>1 0 0 1</ambient>
          <diffuse>0.2 0.2 0.2 1.0</diffuse>
          <specular>0.4 0.4 0.4 1</specular>
          <emissive>0 0 0 0</emissive>
        </material>
      </visual>
    </link>
    <link name='lbr_iiwa_link_1'>
      <pose frame=''>0 0 0.1575 0 -0 0</pose>
      <inertial>
        <pose frame=''>0 -0.03 0.12 0 -0 0</pose>
        <mass>4</mass>
        <inertia>
          <ixx>0.1</ixx>
          <ixy>0</ixy>
          <ixz>0</ixz>
          <iyy>0.09</iyy>
          <iyz>0</iyz>
          <izz>0.02</izz>
        </inertia>
      </inertial>
      <collision name='lbr_iiwa_link_1_collision'>
        <pose frame=''>0 0 0 0 -0 0</pose>
        <geometry>
          <mesh>
            <scale>1 1 1</scale>
            <uri>meshes/link_1.stl</uri>
          </mesh>
        </geometry>
      </collision>
      <visual name='lbr_iiwa_link_1_visual'>
        <pose frame=''>0 0 0 0 -0 0</pose>
        <geometry>
          <mesh>
            <scale>1 1 1</scale>
            <uri>meshes/link_1.obj</uri>
          </mesh>
        </geometry>
        <material>
          <ambient>1 0 0 1</ambient>
          <diffuse>0.5 0.7 1.0 1.0</diffuse>
          <specular>0.5 0.5 0.5 1</specular>
          <emissive>0 0 0 0</emissive>
        </material>
      </visual>
    </link>
    <joint name='J0' type='revolute'>
      <child>lbr_iiwa_link_1</child>
      <parent>lbr_iiwa_link_0</parent>
      <axis>
        <xyz>0 0 1</xyz>
        <limit>
          <lower>-10</lower>
          <upper>10</upper>
          <effort>300</effort>
          <velocity>10</velocity>
        </limit>
        <dynamics>
          <damping>0.5</damping>
          <friction>0</friction>
          <spring_reference>0</spring_reference>
          <spring_stiffness>0</spring_stiffness>
        </dynamics>
      </axis>
    </joint>
    <link name='lbr_iiwa_link_2'>
      <pose frame=''>0 0 0.36 1.5708 -0 -3.14159</pose>
      <inertial>
        <pose frame=''>0.0003 0.059 0.042 0 -0 0</pose>
        <mass>4</mass>
        <inertia>
          <ixx>0.05</ixx>
          <ixy>0</ixy>
          <ixz>0</ixz>
          <iyy>0.018</iyy>
          <iyz>0</iyz>
          <izz>0.044</izz>
        </inertia>
      </inertial>
      <collision name='lbr_iiwa_link_2_collision'>
        <pose frame=''>0 0 0 0 -0 0</pose>
        <geometry>
          <mesh>
            <scale>1 1 1</scale>
            <uri>meshes/link_2.stl</uri>
          </mesh>
        </geometry>
      </collision>
      <visual name='lbr_iiwa_link_2_visual'>
        <pose frame=''>0 0 0 0 -0 0</pose>
        <geometry>
          <mesh>
            <scale>1 1 1</scale>
            <uri>meshes/link_2.obj</uri>
          </mesh>
        </geometry>
        <material>
          <ambient>1 0 0 1</ambient>
          <diffuse>0.5 0.7 1.0 1.0</diffuse>
          <specular>0.5 0.5 0.5 1</specular>
          <emissive>0 0 0 0</emissive>
        </material>
      </visual>
    </link>
    <joint name='J1' type='revolute'>
      <child>lbr_iiwa_link_2</child>
      <parent>lbr_iiwa_link_1</parent>
      <axis>
        <xyz>0 0 1</xyz>
        <limit>
          <lower>-10</lower>
          <upper>10</upper>
          <effort>300</effort>
          <velocity>10</velocity>
        </limit>
        <dynamics>
          <damping>0.5</damping>
          <friction>0</friction>
          <spring_reference>0</spring_reference>
          <spring_stiffness>0</spring_stiffness>
        </dynamics>
      </axis>
    </joint>
    <link name='lbr_iiwa_link_3'>
      <pose frame=''>0 -0 0.5645 0 0 0</pose>
      <inertial>
        <pose frame=''>0 0.03 0.13 0 -0 0</pose>
        <mass>3</mass>
        <inertia>
          <ixx>0.08</ixx>
          <ixy>0</ixy>
          <ixz>0</ixz>
          <iyy>0.075</iyy>
          <iyz>0</iyz>
          <izz>0.01</izz>
        </inertia>
      </inertial>
      <collision name='lbr_iiwa_link_3_collision'>
        <pose frame=''>0 0 0 0 -0 0</pose>
        <geometry>
          <mesh>
            <scale>1 1 1</scale>
            <uri>meshes/link_3.stl</uri>
          </mesh>
        </geometry>
      </collision>
      <visual name='lbr_iiwa_link_3_visual'>
        <pose frame=''>0 0 0 0 -0 0</pose>
        <geometry>
          <mesh>
            <scale>1 1 1</scale>
            <uri>meshes/link_3.obj</uri>
          </mesh>
        </geometry>
        <material>
          <ambient>1 0 0 1</ambient>
          <diffuse>1.0 0.423529411765 0.0392156862745 1.0</diffuse>
          <specular>0.5 0.5 0.5 1</specular>
          <emissive>0 0 0 0</emissive>
        </material>
      </visual>
    </link>
    <joint name='J2' type='revolute'>
      <child>lbr_iiwa_link_3</child>
      <parent>lbr_iiwa_link_2</parent>
      <axis>
        <xyz>0 0 1</xyz>
        <limit>
          <lower>-10</lower>
          <upper>10</upper>
          <effort>300</effort>
          <velocity>10</velocity>
        </limit>
        <dynamics>
          <damping>0.5</damping>
          <friction>0</friction>
          <spring_reference>0</spring_reference>
          <spring_stiffness>0</spring_stiffness>
        </dynamics>
      </axis>
    </joint>
    <link name='lbr_iiwa_link_4'>
      <pose frame=''>0 -0 0.78 1.5708 0 0</pose>
      <inertial>
        <pose frame=''>0 0.067 0.034 0 -0 0</pose>
        <mass>2.7</mass>
        <inertia>
          <ixx>0.03</ixx>
          <ixy>0</ixy>
          <ixz>0</ixz>
          <iyy>0.01</iyy>
          <iyz>0</iyz>
          <izz>0.029</izz>
        </inertia>
      </inertial>
      <collision name='lbr_iiwa_link_4_collision'>
        <pose frame=''>0 0 0 0 -0 0</pose>
        <geometry>
          <mesh>
            <scale>1 1 1</scale>
            <uri>meshes/link_4.stl</uri>
          </mesh>
        </geometry>
      </collision>
      <visual name='lbr_iiwa_link_4_visual'>
        <pose frame=''>0 0 0 0 -0 0</pose>
        <geometry>
          <mesh>
            <scale>1 1 1</scale>
            <uri>meshes/link_4.obj</uri>
          </mesh>
        </geometry>
        <material>
          <ambient>1 0 0 1</ambient>
          <diffuse>0.5 0.7 1.0 1.0</diffuse>
          <specular>0.5 0.5 0.5 1</specular>
          <emissive>0 0 0 0</emissive>
        </material>
      </visual>
    </link>
    <joint name='J3' type='revolute'>
      <child>lbr_iiwa_link_4</child>
      <parent>lbr_iiwa_link_3</parent>
      <axis>
        <xyz>0 0 1</xyz>
        <limit>
          <lower>-10</lower>
          <upper>10</upper>
          <effort>300</effort>
          <velocity>10</velocity>
        </limit>
        <dynamics>
          <damping>0.5</damping>
          <friction>0</friction>
          <spring_reference>0</spring_reference>
          <spring_stiffness>0</spring_stiffness>
        </dynamics>
      </axis>
    </joint>
    <link name='lbr_iiwa_link_5'>
      <pose frame=''>0 -0 0.9645 0 -0 -3.14159</pose>
      <inertial>
        <pose frame=''>0.0001 0.021 0.076 0 -0 0</pose>
        <mass>1.7</mass>
        <inertia>
          <ixx>0.02</ixx>
          <ixy>0</ixy>
          <ixz>0</ixz>
          <iyy>0.018</iyy>
          <iyz>0</iyz>
          <izz>0.005</izz>
        </inertia>
      </inertial>
      <collision name='lbr_iiwa_link_5_collision'>
        <pose frame=''>0 0 0 0 -0 0</pose>
        <geometry>
          <mesh>
            <scale>1 1 1</scale>
            <uri>meshes/link_5.stl</uri>
          </mesh>
        </geometry>
      </collision>
      <visual name='lbr_iiwa_link_5_visual'>
        <pose frame=''>0 0 0 0 -0 0</pose>
        <geometry>
          <mesh>
            <scale>1 1 1</scale>
            <uri>meshes/link_5.obj</uri>
          </mesh>
        </geometry>
        <material>
          <ambient>1 0 0 1</ambient>
          <diffuse>0.5 0.7 1.0 1.0</diffuse>
          <specular>0.5 0.5 0.5 1</specular>
          <emissive>0 0 0 0</emissive>
        </material>
      </visual>
    </link>
    <joint name='J4' type='revolute'>
      <child>lbr_iiwa_link_5</child>
      <parent>lbr_iiwa_link_4</parent>
      <axis>
        <xyz>0 0 1</xyz>
        <limit>
          <lower>-10</lower>
          <upper>10</upper>
          <effort>300</effort>
          <velocity>10</velocity>
        </limit>
        <dynamics>
          <damping>0.5</damping>
          <friction>0</friction>
          <spring_reference>0</spring_reference>
          <spring_stiffness>0</spring_stiffness>
        </dynamics>
      </axis>
    </joint>
    <link name='lbr_iiwa_link_6'>
      <pose frame=''>0 0 1.18 1.5708 -0 -3.14159</pose>
      <inertial>
        <pose frame=''>0 0.0006 0.0004 0 -0 0</pose>
        <mass>1.8</mass>
        <inertia>
          <ixx>0.005</ixx>
          <ixy>0</ixy>
          <ixz>0</ixz>
          <iyy>0.0036</iyy>
          <iyz>0</iyz>
          <izz>0.0047</izz>
        </inertia>
      </inertial>
      <collision name='lbr_iiwa_link_6_collision'>
        <pose frame=''>0 0 0 0 -0 0</pose>
        <geometry>
          <mesh>
            <scale>1 1 1</scale>
            <uri>meshes/link_6.stl</uri>
          </mesh>
        </geometry>
      </collision>
      <visual name='lbr_iiwa_link_6_visual'>
        <pose frame=''>0 0 0 0 -0 0</pose>
        <geometry>
          <mesh>
            <scale>1 1 1</scale>
            <uri>meshes/link_6.obj</uri>
          </mesh>
        </geometry>
        <material>
          <ambient>1 0 0 1</ambient>
          <diffuse>1.0 0.423529411765 0.0392156862745 1.0</diffuse>
          <specular>0.5 0.5 0.5 1</specular>
          <emissive>0 0 0 0</emissive>
        </material>
      </visual>
    </link>
    <joint name='J5' type='revolute'>
      <child>lbr_iiwa_link_6</child>
      <parent>lbr_iiwa_link_5</parent>
      <axis>
        <xyz>0 0 1</xyz>
        <limit>
          <lower>-10</lower>
          <upper>10</upper>
          <effort>300</effort>
          <velocity>10</velocity>
        </limit>
        <dynamics>
          <damping>0.5</damping>
          <friction>0</friction>
          <spring_reference>0</spring_reference>
          <spring_stiffness>0</spring_stiffness>
        </dynamics>
      </axis>
    </joint>
    <link name='lbr_iiwa_link_7'>
      <pose frame=''>0 0 1.261 0 0 0</pose>
      <inertial>
        <pose frame=''>0 0 0.02 0 -0 0</pose>
        <mass>1.3</mass>
        <inertia>
          <ixx>0.001</ixx>
          <ixy>0</ixy>
          <ixz>0</ixz>
          <iyy>0.001</iyy>
          <iyz>0</iyz>
          <izz>0.001</izz>
        </inertia>
      </inertial>
      <collision name='lbr_iiwa_link_7_collision'>
        <pose frame=''>0 0 0 0 -0 0</pose>
        <geometry>
          <mesh>
            <scale>1 1 1</scale>
            <uri>meshes/link_7.stl</uri>
          </mesh>
        </geometry>
      </collision>
      <visual name='lbr_iiwa_link_7_visual'>
        <pose frame=''>0 0 0 0 -0 0</pose>
        <geometry>
          <mesh>
            <scale>1 1 1</scale>
            <uri>meshes/link_7.obj</uri>
          </mesh>
        </geometry>
        <material>
          <ambient>1 0 0 1</ambient>
          <diffuse>0.6 0.6 0.6 1</diffuse>
          <specular>0.5 0.5 0.5 1</specular>
          <emissive>0 0 0 0</emissive>
        </material>
      </visual>
    </link>
    <joint name='J6' type='revolute'>
      <child>lbr_iiwa_link_7</child>
      <parent>lbr_iiwa_link_6</parent>
      <axis>
        <xyz>0 0 1</xyz>
        <limit>
          <lower>-10</lower>
          <upper>10</upper>
          <effort>300</effort>
          <velocity>10</velocity>
        </limit>
        <dynamics>
          <damping>0.5</damping>
          <friction>0</friction>
          <spring_reference>0</spring_reference>
          <spring_stiffness>0</spring_stiffness>
        </dynamics>
      </axis>
    </joint>

    <!-- Attach the base of the gripper to the end of the arm -->
    <joint name='gripper_to_arm' type='continuous'> <!--possibly should be fixed? -->
      <parent>lbr_iiwa_link_7</parent>
      <child>gripah_base</child>
      <axis>
        <xyz>0 0 1</xyz>
      </axis>
    </joint>

    <material name="gray">
      <color rgba="0.89804 0.91765 0.92941 1"/>
    </material>

    <link name="gripah_base">
      <pose frame=''>0 0 1.305 0 -1.570796   0</pose>
      <inertial>
        <pose frame=''>0 0 0 -0.020421 -0 0</pose>
        <!-- <origin rpy="0 0 0" xyz="-0.020421 1.7659E-18 6.5869E-19"/> -->
        <mass>0.18</mass>
        <inertia>
          <ixx>1.0</ixx>
          <ixy>0.0</ixy>
          <ixz>0.0</ixz>
          <iyy>1.0</iyy>
          <iyz>0.0</iyz>
          <izz>1.0</izz>
        </inertia>
      </inertial>
      <visual name="gripah_base_visual">
        <pose frame=''>0 0 0 0 0 0</pose>
        <!-- <origin rpy="0 0 0" xyz="0 0 0"/> -->
        <geometry>
          <mesh>
            <scale>1 1 1</scale>
            <uri>meshes/wrist.STL</uri>
          </mesh>
        </geometry>
        <material name="gray"/>
      </visual>
      <collision name="gripah_base_collision">
        <pose frame=''>0 0 0 0 0 0</pose>
        <!-- <origin rpy="0 0 0" xyz="0 0 0"/> -->
        <geometry>
          <mesh>
            <scale>1 1 1</scale>
            <uri>meshes/wrist.STL</uri>
          </mesh>
        </geometry>
      </collision>
    </link>

    <link name="wide_finger_link">
      <pose frame=''>0 0 1.360 1.5708 -1.557463 0</pose>
      <inertial>
        <pose frame=''>0.056976 0.015337 0 0 0 0</pose>
        <mass>0.0167</mass>
        <inertia>
          <ixx>1.0</ixx>
          <ixy>-0.01</ixy>
          <ixz>0.0</ixz>
          <iyy>1.0</iyy>
          <iyz>0.0</iyz>
          <izz>1.0</izz>
        </inertia>
      </inertial>
      <visual>
        <pose frame=''>0 0 0 0 0 0</pose>
        <geometry>
          <mesh>
            <scale>1 1 1</scale>
            <uri>meshes/wide_finger.STL</uri>
          </mesh>
        </geometry>
        <material name="gray"/>
      </visual>
      <collision>
        <pose frame=''>0 0 0 0 0 0</pose>
        <geometry>
          <mesh>
            <scale>1 1 1</scale>
            <uri>meshes/wide_finger.STL</uri>
          </mesh>
        </geometry>
      </collision>
    </link>

    <joint name="wide_finger_joint" type="revolute">
      <parent>gripah_base</parent>
      <child>wide_finger_link</child>
      <axis>
        <xyz>0 0 1</xyz>
        <limit>
          <effort>6.6</effort>
          <lower>-1.0472</lower>
          <upper>1.0472</upper>
          <velocity>8.0</velocity>
        </limit>
      </axis>
    </joint>

    <link name="narrow_finger_link">
      <pose>0 0 1.360 1.5708 -1.557463 0</pose>
      <inertial>
        <pose>0.052556 0.013896 0 0 0 0</pose>
        <mass>0.016641</mass>
        <inertia>
          <ixx>1.0</ixx>
          <ixy>-0.03</ixy>
          <ixz>0.0</ixz>
          <iyy>1.0</iyy>
          <iyz>0.0</iyz>
          <izz>1.0</izz>
        </inertia>
      </inertial>
      <visual>
        <pose>0 0 0 0 0 0</pose>
        <geometry>
          <mesh>
            <scale>1 1 1</scale>
            <uri>meshes/narrow_finger.STL</uri>
          </mesh>
        </geometry>
        <material name="gray"/>
      </visual>
      <collision>
        <pose>0 0 0 0 0 0</pose>
        <geometry>
          <mesh>
            <scale>1 1 1</scale>
            <uri>meshes/narrow_finger.STL</uri>
          </mesh>
        </geometry>
      </collision>
    </link>

    <joint name="narrow_finger_joint" type="revolute">
      <parent>gripah_base</parent>
      <child>narrow_finger_link</child>
      <axis>
        <xyz>0 0 -1</xyz>
        <limit>
          <effort>6.6</effort>
          <lower>-1.0472</lower>
          <upper>1.0472</upper>
          <velocity>8.0</velocity>
        </limit>
      </axis>
    </joint>


  </model>
</world>
</sdf>
